Workbook

Sheet Base Inversionistas
J3: 2025
A4: NO. | B4: NOMBRES | C4: NO. IDENTIFICACION | D4: NO. CELULAR | E4: LOCALIDAD | F4: No. Cuotas | G4: SALDO A DIC2024 | H4: FORMA | I4: TIPO DE MOVIMIENTO | J4: ENERO | K4: FEBRERO | L4: MARZO | M4: ABRIL | N4: MAYO | O4: JUNIO | P4: JULIO | Q4: AGOSTO | R4: SEPTIEMBRE | S4: OCTUBRE | T4: NOVIEMBRE | U4: DICIEMBRE | V4: ENERO | W4: Total_Aportes | X4: Cuotas_Calculadas | Y4: Meses_Con_Aporte | Z4: Cuotas_Enteras
A5: 1 | B5: ABNER GONZALEZ | C5: 9289920 | E5: Medellin | F5: 1 | G5: 859000 | H5: BCOL AHO | I5: CREDITO | N5: 800000 | R5: 400000 | S5: 0 | T5: 0 | U5: 0 | V5: =VLOOKUP(B5,'[1]INV. 2026'!$B:$J,9,0) -> 0 | W5: =SUM(J5:V5) -> 1200000 | X5: =W5/400000 -> 3 | Y5: =COUNTIF(J5:V5,">0") -> 2 | Z5: =ROUNDUP(X5,0) -> 3
A6: 2 | B6: ALBA MARINA ROMERO | I6: CREDITO | N6: 100000 | R6: 0 | S6: 0 | T6: 0 | U6: 0 | V6: =VLOOKUP(B6,'[1]INV. 2026'!$B:$J,9,0) -> 0 | W6: =SUM(J6:V6) -> 100000 | X6: =W6/400000 -> 0.25 | Y6: =COUNTIF(J6:V6,">0") -> 1 | Z6: =ROUNDUP(X6,0) -> 1
A7: 3 | B7: ANA MISAD | E7: BOGOTA | G7: 200000 | H7: EFECTIVO | I7: CREDITO | R7: 0 | S7: 0 | T7: 0 | U7: 0 | V7: =VLOOKUP(B7,'[1]INV. 2026'!$B:$J,9,0) -> 0 | W7: =SUM(J7:V7) -> 0 | X7: =W7/400000 -> 0 | Y7: =COUNTIF(J7:V7,">0") -> 0 | Z7: =ROUNDUP(X7,0) -> 0
A8: 4 | B8: ANA CORTES | E8: BOGOTA | G8: 0 | H8: EFECTIVO | I8: CREDITO | K8: 100000 | R8: 0 | S8: 0 | T8: 0 | U8: 0 | V8: =VLOOKUP(B8,'[1]INV. 2026'!$B:$J,9,0) -> 0 | W8: =SUM(J8:V8) -> 100000 | X8: =W8/400000 -> 0.25 | Y8: =COUNTIF(J8:V8,">0") -> 1 | Z8: =ROUNDUP(X8,0) -> 1
A9: 5 | B9: ANA MARIA PORTILLA CLAROS | C9: 1114621012 | D9: 3207945735 | E9: BOGOTA | G9: 1000000 | H9: BCOL AHO | I9: CREDITO | J9: 400000 | R9: 0 | S9: 0 | T9: 200000 | U9: 400000 | V9: =VLOOKUP(B9,'[1]INV. 2026'!$B:$J,9,0) -> 0 | W9: =SUM(J9:V9) -> 1000000 | X9: =W9/400000 -> 2.5 | Y9: =COUNTIF(J9:V9,">0") -> 3 | Z9: =ROUNDUP(X9,0) -> 3
A10: 6 | B10: ANDRES CASTRILLON "GIRARDOTA" | C10: 1035855590 | E10: Girardota | G10: 200000 | H10: BCOL AHO | I10: CREDITO | P10: 100000 | R10: 0 | S10: 0 | T10: 400000 | U10: 400000 | V10: =VLOOKUP(B10,'[1]INV. 2026'!$B:$J,9,0) -> 0 | W10: =SUM(J10:V10) -> 900000 | X10: =W10/400000 -> 2.25 | Y10: =COUNTIF(J10:V10,">0") -> 3 | Z10: =ROUNDUP(X10,0) -> 3
A11: 7 | B11: ANDRES MORENO | C11: 1077465696 | D11: 3207593131 | E11: CHOCO | I11: CREDITO | N11: 400000 | Q11: 400000 | R11: 0 | S11: 0 | T11: 0 | U11: 800000 | V11: =VLOOKUP(B11,'[1]INV. 2026'!$B:$J,9,0) -> 0 | W11: =SUM(J11:V11) -> 1600000 | X11: =W11/400000 -> 4 | Y11: =COUNTIF(J11:V11,">0") -> 3 | Z11: =ROUNDUP(X11,0) -> 4
A12: 8 | B12: ANGIE FINO | I12: CREDITO | O12: 1000000 | R12: 0 | S12: 0 | T12: 0 | U12: 0 | V12: =VLOOKUP(B12,'[1]INV. 2026'!$B:$J,9,0) -> 0 | W12: =SUM(J12:V12) -> 1000000 | X12: =W12/400000 -> 2.5 | Y12: =COUNTIF(J12:V12,">0") -> 1 | Z12: =ROUNDUP(X12,0) -> 3
A13: 9 | B13: ANONIMO | E13: BOGOTA | I13: CREDITO | N13: 380000 | O13: 200000 | R13: 0 | S13: 0 | T13: 0 | U13: 0 | V13: =VLOOKUP(B13,'[1]INV. 2026'!$B:$J,9,0) -> 0 | W13: =SUM(J13:V13) -> 580000 | X13: =W13/400000 -> 1.45 | Y13: =COUNTIF(J13:V13,">0") -> 2 | Z13: =ROUNDUP(X13,0) -> 2
A14: 10 | B14: BENITO HERRRA | F14: 3 | G14: 1200000 | H14: BCOL AHO | I14: CREDITO | R14: 0 | S14: 0 | T14: 400000 | U14: 0 | V14: =VLOOKUP(B14,'[1]INV. 2026'!$B:$J,9,0) -> 0 | W14: =SUM(J14:V14) -> 400000 | X14: =W14/400000 -> 1 | Y14: =COUNTIF(J14:V14,">0") -> 1 | Z14: =ROUNDUP(X14,0) -> 1
A15: 11 | B15: BIBIANA MONTOYA RODAS | G15: 1500000 | H15: BCOL AHO | I15: CREDITO | R15: 0 | S15: 0 | T15: 0 | U15: 0 | V15: =VLOOKUP(B15,'[1]INV. 2026'!$B:$J,9,0) -> 0 | W15: =SUM(J15:V15) -> 0 | X15: =W15/400000 -> 0 | Y15: =COUNTIF(J15:V15,">0") -> 0 | Z15: =ROUNDUP(X15,0) -> 0
A16: 12 | B16: BRAYER ALEXIS QUINTERO FERNANDEZ | E16: CUCUTA | G16: 820000 | H16: BCOL AHO | I16: CREDITO | L16: 400000 | Q16: 400000 | R16: 400000 | S16: 400000 | T16: 0 | U16: 400000 | V16: =VLOOKUP(B16,'[1]INV. 2026'!$B:$J,9,0) -> 400000 | W16: =SUM(J16:V16) -> 2400000 | X16: =W16/400000 -> 6 | Y16: =COUNTIF(J16:V16,">0") -> 6 | Z16: =ROUNDUP(X16,0) -> 6
A17: 13 | B17: CARLIS MICHELE PEREZ CANO | C17: 1095846194 | D17: 3022962452 | E17: BOGOTA | H17: BCOL AHO | I17: CREDITO | L17: 400000 | N17: 200000 | R17: 0 | S17: 0 | T17: 400000 | U17: 0 | V17: =VLOOKUP(B17,'[1]INV. 2026'!$B:$J,9,0) -> 0 | W17: =SUM(J17:V17) -> 1000000 | X17: =W17/400000 -> 2.5 | Y17: =COUNTIF(J17:V17,">0") -> 3 | Z17: =ROUNDUP(X17,0) -> 3
A18: 14 | B18: CARLOS CARRASCO | E18: BOGOTA | F18: 1 | G18: 1320000 | H18: EFECTIVO | I18: CREDITO | J18: 400000 | K18: 424000 | L18: 425000 | M18: 450000 | N18: 400000 | O18: 400000 | P18: 400000 | Q18: 400000 | R18: 400000 | S18: 400000 | T18: 400000 | U18: 400000 | V18: =VLOOKUP(B18,'[1]INV. 2026'!$B:$J,9,0) -> 400000 | W18: =SUM(J18:V18) -> 5299000 | X18: =W18/400000 -> 13.2475 | Y18: =COUNTIF(J18:V18,">0") -> 13 | Z18: =ROUNDUP(X18,0) -> 14
A19: 15 | B19: CARLOS PALMA | E19: BOGOTA | F19: 1 | G19: 1200000 | H19: EFECTIVO | I19: CREDITO | K19: 400000 | L19: 400000 | M19: 400000 | N19: 400000 | P19: 400000 | Q19: 400000 | R19: 0 | S19: 400000 | T19: 400000 | U19: 400000 | V19: =VLOOKUP(B19,'[1]INV. 2026'!$B:$J,9,0) -> 0 | W19: =SUM(J19:V19) -> 3600000 | X19: =W19/400000 -> 9 | Y19: =COUNTIF(J19:V19,">0") -> 9 | Z19: =ROUNDUP(X19,0) -> 9
A20: 16 | B20: CARLOS ANDRES COCUY | C20: 14797460 | D20: 3160438302 | E20: DOSQUEBRADAS | G20: 0 | H20: BCOL AHO | I20: CREDITO | J20: 400000 | K20: 400000 | L20: 400000 | M20: 400000 | N20: 400000 | O20: 400000 | P20: 400000 | Q20: 400000 | R20: 450000 | S20: 650000 | T20: 0 | U20: 900000 | V20: =VLOOKUP(B20,'[1]INV. 2026'!$B:$J,9,0) -> 0 | W20: =SUM(J20:V20) -> 5200000 | X20: =W20/400000 -> 13 | Y20: =COUNTIF(J20:V20,">0") -> 11 | Z20: =ROUNDUP(X20,0) -> 13
A21: 17 | B21: CAROLINA QUIROGA | G21: 0 | H21: BCOL AHO | I21: CREDITO | L21: 100000 | R21: 0 | S21: 0 | T21: 0 | U21: 0 | V21: =VLOOKUP(B21,'[1]INV. 2026'!$B:$J,9,0) -> 0 | W21: =SUM(J21:V21) -> 100000 | X21: =W21/400000 -> 0.25 | Y21: =COUNTIF(J21:V21,">0") -> 1 | Z21: =ROUNDUP(X21,0) -> 1
A22: 18 | B22: CESAR VERA | C22: 79333423 | D22: 3166268412 | E22: BOGOTA | F22: 3 | G22: 4000000 | H22: EFECTIVO | I22: CREDITO | J22: 800000 | K22: 2000000 | L22: 1200000 | M22: 1600000 | N22: 1200000 | O22: 1600000 | P22: 1700000 | Q22: 1200000 | R22: 1600000 | S22: 2000000 | T22: 2400000 | U22: 1600000 | V22: =VLOOKUP(B22,'[1]INV. 2026'!$B:$J,9,0) -> 1200000 | W22: =SUM(J22:V22) -> 20100000 | X22: =W22/400000 -> 50.25 | Y22: =COUNTIF(J22:V22,">0") -> 13 | Z22: =ROUNDUP(X22,0) -> 51
A23: 19 | B23: CLAUDIA ARCINIEGAS | G23: 0 | H23: BCOL AHO | I23: CREDITO | L23: 400000 | N23: 400000 | R23: 0 | S23: 0 | T23: 0 | U23: 0 | V23: =VLOOKUP(B23,'[1]INV. 2026'!$B:$J,9,0) -> 0 | W23: =SUM(J23:V23) -> 800000 | X23: =W23/400000 -> 2 | Y23: =COUNTIF(J23:V23,">0") -> 2 | Z23: =ROUNDUP(X23,0) -> 2
A24: 20 | B24: DANIEL VARGAS | E24: NEIVA | F24: 1 | G24: 1200000 | H24: BCOL AHO | I24: CREDITO | R24: 0 | S24: 0 | T24: 0 | U24: 0 | V24: =VLOOKUP(B24,'[1]INV. 2026'!$B:$J,9,0) -> 400000 | W24: =SUM(J24:V24) -> 400000 | X24: =W24/400000 -> 1 | Y24: =COUNTIF(J24:V24,">0") -> 1 | Z24: =ROUNDUP(X24,0) -> 1
A25: 21 | B25: DANIELA CASTO | G25: 0 | H25: BCOL AHO | I25: CREDITO | K25: 200000 | R25: 0 | S25: 0 | T25: 0 | U25: 0 | V25: =VLOOKUP(B25,'[1]INV. 2026'!$B:$J,9,0) -> 0 | W25: =SUM(J25:V25) -> 200000 | X25: =W25/400000 -> 0.5 | Y25: =COUNTIF(J25:V25,">0") -> 1 | Z25: =ROUNDUP(X25,0) -> 1
A26: 22 | B26: DAVID MAESTRE | G26: 1200000 | H26: BCOL AHO | I26: CREDITO | K26: 200000 | M26: 400000 | N26: 200000 | P26: 400000 | R26: 0 | S26: 0 | T26: 0 | U26: 0 | V26: =VLOOKUP(B26,'[1]INV. 2026'!$B:$J,9,0) -> 0 | W26: =SUM(J26:V26) -> 1200000 | X26: =W26/400000 -> 3 | Y26: =COUNTIF(J26:V26,">0") -> 4 | Z26: =ROUNDUP(X26,0) -> 3
A27: 23 | B27: DAVID MIRANDA | E27: BOGOTA | F27: 1 | G27: 400000 | H27: BCOL AHO | I27: CREDITO | J27: 400000 | K27: 0 | L27: 400000 | N27: 400000 | P27: 800000 | Q27: 400000 | R27: 400000 | S27: 400000 | T27: 400000 | U27: 400000 | V27: =VLOOKUP(B27,'[1]INV. 2026'!$B:$J,9,0) -> 0 | W27: =SUM(J27:V27) -> 4000000 | X27: =W27/400000 -> 10 | Y27: =COUNTIF(J27:V27,">0") -> 9 | Z27: =ROUNDUP(X27,0) -> 10
A28: 24 | B28: EDDWARD GARCIA | E28: BOGOTA | F28: 1 | G28: 240000 | H28: EFECTIVO | I28: CREDITO | R28: 0 | S28: 0 | T28: 0 | U28: 0 | V28: =VLOOKUP(B28,'[1]INV. 2026'!$B:$J,9,0) -> 0 | W28: =SUM(J28:V28) -> 0 | X28: =W28/400000 -> 0 | Y28: =COUNTIF(J28:V28,">0") -> 0 | Z28: =ROUNDUP(X28,0) -> 0
A29: 25 | B29: ERICA PLATA | C29: 60362206 | D29: 3165652640 | E29: LOS PATIOS | F29: 1 | G29: 200000 | H29: BCOL AHO 2 | I29: CREDITO | R29: 0 | S29: 0 | T29: 400000 | U29: 400000 | V29: =VLOOKUP(B29,'[1]INV. 2026'!$B:$J,9,0) -> 0 | W29: =SUM(J29:V29) -> 800000 | X29: =W29/400000 -> 2 | Y29: =COUNTIF(J29:V29,">0") -> 2 | Z29: =ROUNDUP(X29,0) -> 2
A30: 26 | B30: ERMILGEN RIAÑO | E30: BOGOTA | G30: 100000 | H30: EFECTIVO | I30: CREDITO | R30: 0 | S30: 0 | T30: 0 | U30: 0 | V30: =VLOOKUP(B30,'[1]INV. 2026'!$B:$J,9,0) -> 0 | W30: =SUM(J30:V30) -> 0 | X30: =W30/400000 -> 0 | Y30: =COUNTIF(J30:V30,">0") -> 0 | Z30: =ROUNDUP(X30,0) -> 0
A31: 27 | B31: ESTEBAN ISAZA MUÑOZ | C31: 88230239 | D31: 3123933769 | E31: PAMPLONA | F31: 1 | G31: 2860000 | H31: BCOL AHO 2 | I31: CREDITO | J31: 830000 | K31: 830000 | M31: 830000 | N31: 830000 | P31: 830000 | R31: 830000 | S31: 0 | T31: 605000 | U31: 1600000 | V31: =VLOOKUP(B31,'[1]INV. 2026'!$B:$J,9,0) -> 1600000 | W31: =SUM(J31:V31) -> 8785000 | X31: =W31/400000 -> 21.9625 | Y31: =COUNTIF(J31:V31,">0") -> 9 | Z31: =ROUNDUP(X31,0) -> 22
A32: 28 | B32: ESTHER TORRES | E32: BOGOTA | G32: 450000 | H32: EFECTIVO | I32: CREDITO | R32: 0 | S32: 0 | T32: 0 | U32: 0 | V32: =VLOOKUP(B32,'[1]INV. 2026'!$B:$J,9,0) -> 0 | W32: =SUM(J32:V32) -> 0 | X32: =W32/400000 -> 0 | Y32: =COUNTIF(J32:V32,">0") -> 0 | Z32: =ROUNDUP(X32,0) -> 0
A33: 29 | B33: EUSEBIO MONTES | F33: 1 | G33: 0 | H33: No Registra | I33: CREDITO | R33: 0 | S33: 0 | T33: 0 | U33: 0 | V33: =VLOOKUP(B33,'[1]INV. 2026'!$B:$J,9,0) -> 0 | W33: =SUM(J33:V33) -> 0 | X33: =W33/400000 -> 0 | Y33: =COUNTIF(J33:V33,">0") -> 0 | Z33: =ROUNDUP(X33,0) -> 0
A34: 30 | B34: FLOR ACUÑA | E34: BOGOTA | G34: 400000 | H34: BCOL AHO | I34: CREDITO | R34: 0 | S34: 0 | T34: 0 | U34: 0 | V34: =VLOOKUP(B34,'[1]INV. 2026'!$B:$J,9,0) -> 0 | W34: =SUM(J34:V34) -> 0 | X34: =W34/400000 -> 0 | Y34: =COUNTIF(J34:V34,">0") -> 0 | Z34: =ROUNDUP(X34,0) -> 0
A35: 31 | B35: FLOR SALAMANCA | C35: 23963745 | D35: 3142385522 | E35: BOGOTA | F35: 2 | G35: 4400000 | H35: BCOL AHO-EF | I35: CREDITO | J35: 1200000 | K35: 0 | L35: 1200000 | M35: 1200000 | O35: 1200000 | P35: 1600000 | Q35: 2000000 | R35: 0 | S35: 2000000 | T35: 3200000 | U35: 3600000 | V35: =VLOOKUP(B35,'[1]INV. 2026'!$B:$J,9,0) -> 3600000 | W35: =SUM(J35:V35) -> 20800000 | X35: =W35/400000 -> 52 | Y35: =COUNTIF(J35:V35,">0") -> 10 | Z35: =ROUNDUP(X35,0) -> 52
A36: 32 | B36: FRANCISCO VILLAMIL | E36: BOGOTA | G36: 0 | H36: EFECTIVO | I36: CREDITO | K36: 200000 | Q36: 400000 | R36: 400000 | S36: 400000 | T36: 400000 | U36: 400000 | V36: =VLOOKUP(B36,'[1]INV. 2026'!$B:$J,9,0) -> 400000 | W36: =SUM(J36:V36) -> 2600000 | X36: =W36/400000 -> 6.5 | Y36: =COUNTIF(J36:V36,">0") -> 7 | Z36: =ROUNDUP(X36,0) -> 7
A37: 33 | B37: FREIMAN JAIMES | C37: 13177594 | D37: 3107951023 | E37: OCAÑA | F37: 1 | G37: 0 | H37: No Registra | I37: CREDITO | R37: 400000 | S37: 400000 | T37: 0 | U37: 0 | V37: =VLOOKUP(B37,'[1]INV. 2026'!$B:$J,9,0) -> 0 | W37: =SUM(J37:V37) -> 800000 | X37: =W37/400000 -> 2 | Y37: =COUNTIF(J37:V37,">0") -> 2 | Z37: =ROUNDUP(X37,0) -> 2
A38: 34 | B38: GISEL DANIELA GUTIERREZ MURILLO | G38: 400000 | H38: BCOL AHO | I38: CREDITO | K38: 400000 | M38: 400000 | R38: 0 | S38: 0 | T38: 0 | U38: 0 | V38: =VLOOKUP(B38,'[1]INV. 2026'!$B:$J,9,0) -> 0 | W38: =SUM(J38:V38) -> 800000 | X38: =W38/400000 -> 2 | Y38: =COUNTIF(J38:V38,">0") -> 2 | Z38: =ROUNDUP(X38,0) -> 2
A39: 35 | B39: GUILLERMO MONSALVE | C39: 4803428 | D39: 3009838761 | E39: SINCELEJO | G39: 800000 | H39: BCOL AHO | I39: CREDITO | K39: 400000 | M39: 400000 | N39: 400000 | R39: 800000 | S39: 0 | T39: 1600000 | U39: 0 | V39: =VLOOKUP(B39,'[1]INV. 2026'!$B:$J,9,0) -> 0 | W39: =SUM(J39:V39) -> 3600000 | X39: =W39/400000 -> 9 | Y39: =COUNTIF(J39:V39,">0") -> 5 | Z39: =ROUNDUP(X39,0) -> 9
A40: 36 | B40: HERMES PATIÑO | C40: 93206783 | D40: 3125188563 | E40: SINCELEJO | G40: 800000 | H40: BCOL AHO | I40: CREDITO | J40: 400000 | K40: 400000 | M40: 400000 | N40: 400000 | O40: 400000 | P40: 400000 | Q40: 400000 | R40: 800000 | S40: 800000 | T40: 800000 | U40: 0 | V40: =VLOOKUP(B40,'[1]INV. 2026'!$B:$J,9,0) -> 0 | W40: =SUM(J40:V40) -> 5200000 | X40: =W40/400000 -> 13 | Y40: =COUNTIF(J40:V40,">0") -> 10 | Z40: =ROUNDUP(X40,0) -> 13
A41: 37 | B41: HUMBERTO OSPINO | C41: 72147202 | D41: 3126317467 | E41: ENVIGADO | G41: 1200000 | H41: BCOL AHO 2 | I41: CREDITO | L41: 800000 | M41: 400000 | O41: 400000 | R41: 0 | S41: 800000 | T41: 400000 | U41: 400000 | V41: =VLOOKUP(B41,'[1]INV. 2026'!$B:$J,9,0) -> 0 | W41: =SUM(J41:V41) -> 3200000 | X41: =W41/400000 -> 8 | Y41: =COUNTIF(J41:V41,">0") -> 6 | Z41: =ROUNDUP(X41,0) -> 8
A42: 38 | B42: IG. EN PTO. COLOMBIA | E42: Barranquilla | G42: 2812000 | H42: BCOL AHO | I42: CREDITO | J42: 1030000 | K42: 1020000 | N42: 1020000 | Q42: 640000 | R42: 0 | S42: 0 | T42: 0 | U42: 0 | V42: =VLOOKUP(B42,'[1]INV. 2026'!$B:$J,9,0) -> 0 | W42: =SUM(J42:V42) -> 3710000 | X42: =W42/400000 -> 9.275 | Y42: =COUNTIF(J42:V42,">0") -> 4 | Z42: =ROUNDUP(X42,0) -> 10
...

Sheet Gastos
A4: NO. | B4: CLASIF | C4: NOMBRES | D4: NO. IDENTIFICACION | E4: NO. CELULAR | F4: LOCALIDAD | G4: No. Cuotas | H4: SALDO A DIC2024 | I4: FORMA | J4: TIPO DE MOVIMIENTO | K4: ENERO | L4: FEBRERO | M4: MARZO | N4: ABRIL | O4: MAYO | P4: JUNIO | Q4: JULIO | R4: AGOSTO | S4: SEPTIEMBRE | T4: OCTUBRE | U4: NOVIEMBRE | V4: DICIEMBRE | W4: ENERO
A5: 1 | B5: OFRENDA | C5: OFRENDA JORGE LUIS BARRIOS | J5: CREDITO | Q5: -2600000
A6: =A5+1 -> 2 | B6: DEUDA FONDO | C6: DEUDA COLPORTAJE | J6: CREDITO | K6: -3000000 | L6: -3000000 | M6: -3000000 | N6: -3000000 | O6: -3000000 | P6: -3000000 | Q6: -3000000 | R6: -3000000 | S6: -3000000 | T6: -3000000 | U6: -3000000 | V6: -3000000
A7: =A6+1 -> 3 | B7: PAC | C7: APOYO CASA PAC | H7: -12000000 | J7: DEBITO | K7: -2700000 | L7: -3500000
A8: =A7+1 -> 4 | B8: PAC | C8: APOYO CASA PAC | H8: -5231807 | I8: BCOL AHO | J8: DEBITO
A9: =A8+1 -> 5 | B9: PAC | C9: APOYO CASA PAC | H9: -3500000 | I9: BCOL ALHO | J9: DEBITO
A10: =A9+1 -> 6 | B10: CEPEV | C10: APOYO CEPPEV | H10: 0 | I10: BCOL AHO | J10: DEBITO | K10: -5000000 | L10: -5000000 | M10: -5000000 | N10: -5000000 | O10: -5000000 | P10: -5000000 | Q10: -5000000
A11: =A10+1 -> 7 | B11: BRASIL | C11: APOYO HNOS. EN BRASIL | H11: -20000000 | I11: BCOL AHO | J11: DEBITO | N11: -592000
A12: =A11+1 -> 8 | B12: PAC | C12: APOYO PERU PAC | J12: DEBITO | L12: -1667500
A13: =A12+1 -> 9 | B13: PAC | C13: ARRIENDO CASA PAC | H13: 0 | I13: BCOL CTE | J13: DEBITO
A14: =A13+1 -> 10 | B14: PAC | C14: ARRIENDO CASA PAC | H14: 0 | J14: DEBITO
A15: =A14+1 -> 11 | B15: INVERSIONISTAS | C15: COMPRA CELULAR | H15: -6700000 | I15: BCOL AHO | J15: DEBITO | N15: -769900
A16: =A15+1 -> 12 | B16: PEDRO D | C16: ENTREGA RESERVA PEDRO DONG | J16: DEBITO | M16: -31000000 | N16: -31000000
A17: =A16+1 -> 13 | B17: EAV | C17: ENVIO EAV | H17: -12300000 | J17: DEBITO | N17: -12015000
A18: =A17+1 -> 14 | B18: COSTA RICA | C18: OBRA COSTA RICA | J18: DEBITO | L18: -4620900
A19: =A18+1 -> 15 | B19: OFRENDA | C19: OFRENDA A JONES COSTA | H19: -400000 | I19: BCOL AHO | J19: DEBITO | M19: -1100000
A20: =A19+1 -> 16 | B20: PAC | C20: PAGO DEUDA ARRIENDO PAC | H20: 0 | I20: BCOL AHO | J20: DEBITO
A21: =A20+1 -> 17 | B21: CUBA | C21: VIATICOS CUBA | I21: BCOL AHO | J21: DEBITO | K21: -1477000
A22: =A21+1 -> 18 | B22: OFRENDA | C22: VIATICOS EUROPA DAVID MAESTRE | H22: -6413915 | J22: DEBITO | N22: -2000000
A23: =A22+1 -> 19 | B23: OFRENDA | C23: VIATICOS JONES | H23: 0 | I23: EFECTIVO | J23: DEBITO | M23: -2846000
A24: =A23+1 -> 20 | B24: EAV | C24: VIATICOS EAV DE RESERVA PEDRO D | I24: BCOL AHO | J24: DEBITO | O24: -4229600
A25: =A24+1 -> 21 | B25: IVPT | C25: GASTOS IVPT | H25: 0 | I25: BCOL AHO | J25: DEBITO | O25: -22131200
A26: =A25+1 -> 22 | B26: PANAMA | C26: ENTREGA A DAVID MAESTRE PANAMA | J26: DEBITO | P26: -7000000
A27: =A26+1 -> 23 | B27: VUELOS | C27: ENTREGA A DAVID M RESERVA PEDRO | J27: DEBITO | P27: -5000000
A28: =A27+1 -> 24 | B28: CEPEV | C28: APOYO CENA CEPPEV | J28: DEBITO | P28: -3000000
A29: =A28+1 -> 25 | B29: PEDRO D | C29: ENTREGA RESERVA PEDRO DONG | J29: DEBITO | P29: -41400000
A30: =A29+1 -> 26 | B30: PANAMA | C30: APOYO PAC PANAMA | J30: DEBITO | P30: -1000000
A31: =A30+1 -> 27 | B31: VUELOS | C31: ENTREGA DAVID MIRANDA RESERVA PD | J31: DEBITO | Q31: -7598700
A32: =A31+1 -> 28 | B32: VUELOS | C32: ENTREGA DAVID MIRANDA RESERVA PD | J32: DEBITO | Q32: -3575640
A33: =A32+1 -> 29 | B33: PANAMA | C33: APOYO PAC PANAMA | J33: DEBITO | Q33: -1000000
A34: =A33+1 -> 30 | B34: PEDRO D | C34: ENTREGA RESERVA PEDRO DONG | J34: DEBITO | Q34: -20350000
A35: =A34+1 -> 31 | B35: PANAMA | C35: LUIS MIGUEL NARANJO APOYO PANAMA | J35: DEBITO | R35: -1000000
A36: =A35+1 -> 32 | B36: VUELOS | C36: VIATICOS COLPORTORES | J36: DEBITO | R36: -459000
A37: =A36+1 -> 33 | B37: OFRENDA | C37: APOYO LUIS GABRIEL BRASIL | J37: DEBITO | R37: -2375000
A38: =A37+1 -> 34 | B38: JULIO S | C38: VIATICOS ECUADOR JULIO SANCHEA | J38: DEBITO | R38: -3844290
A39: =A38+1 -> 35 | B39: PEDRO D | C39: ENTREGA PEDRO DONG | J39: DEBITO | R39: -12045000
A40: =A39+1 -> 36 | B40: EAV | C40: ENTREGA A ESTANCIA | J40: DEBITO | R40: -11190450
A41: =A40+1 -> 37 | B41: PANAMA | C41: APOYO PAC PANAMA | J41: DEBITO | R41: -1100000
A42: =A41+1 -> 38 | B42: JULIO S | C42: JULIO SANCHEZ VIATICOS LILMA | J42: DEBITO | S42: -2284620
A43: =A42+1 -> 39 | B43: CEPEV | C43: APOYO CEPPEV | J43: DEBITO | S43: -3200000
...

Sheet Resumen 2025
A1: INDICADORES CLAVE
I2: OCT | J2: NOV | K2: DIC
A3: MES | B3: TOTAL APORTES | C3: INVERSIONISTAS ACTIVOS | E3: MES | F3: TOTAL GASTOS | H3: NUEVOS INV (OCT) | I3: =COUNTIFS('Base Inversionistas'!R5:R296,"=0",'Base Inversionistas'!S5:S296,">0") -> 34 | J3: =COUNTIFS('Base Inversionistas'!S5:S296,"=0",'Base Inversionistas'!T5:T296,">0") -> 81 | K3: =COUNTIFS('Base Inversionistas'!T5:T296,"=0",'Base Inversionistas'!U5:U296,">0") -> 39
A4: 2024 | B4: 102568000 | E4: 2024 | F4: ='Gastos 26'!H123 -> -66545722 | H4: BAJAS INV | I4: =COUNTIFS('Base Inversionistas'!R6:R297,">0",'Base Inversionistas'!S6:S297,"=0") -> 23 | J4: =COUNTIFS('Base Inversionistas'!S6:S297,">0",'Base Inversionistas'!T6:T297,"=0") -> 31 | K4: =COUNTIFS('Base Inversionistas'!T6:T297,">0",'Base Inversionistas'!U6:U297,"=0") -> 29
A5: ENERO | B5: =SUM('Base Inversionistas'!J5:J268) -> 23082000 | C5: =COUNTIF('Base Inversionistas'!J5:J268,">0") -> 32 | E5: ENERO | F5: =SUM('Gastos 26'!K5:K122) -> -14223540
A6: FEBRERO | B6: =SUM('Base Inversionistas'!K5:K268) -> 19771600 | C6: 37 | E6: FEBRERO | F6: -17788400
A7: MARZO | B7: =SUM('Base Inversionistas'!L5:L268) -> 40867000 | C7: 43 | E7: MARZO | F7: -42946000 | H7: CLASIFICACION GASTOS | I7: Suma de ENERO | J7: Suma de FEBRERO | K7: Suma de MARZO | L7: Suma de ABRIL | M7: Suma de MAYO | N7: Suma de JUNIO | O7: Suma de JULIO | P7: Suma de AGOSTO | Q7: Suma de SEPTIEMBRE | R7: Suma de OCTUBRE | S7: Suma de NOVIEMBRE | T7: Suma de DICIEMBRE | U7: TOTAL
A8: ABRIL | B8: =SUM('Base Inversionistas'!M5:M268) -> 42217250 | C8: 58 | E8: ABRIL | F8: -54376900 | H8: BRASIL | L8: -592000 | U8: =SUM(I8:S8) -> -592000
A9: MAYO | B9: =SUM('Base Inversionistas'!N5:N268) -> 53415000 | C9: 71 | E9: MAYO | F9: -34360800 | H9: CEPEV | I9: -5000000 | J9: -5000000 | K9: -5000000 | L9: -5000000 | M9: -5000000 | N9: -8000000 | O9: -5000000 | Q9: -3200000 | R9: -16000000 | T9: -1000000 | U9: =SUM(I9:S9) -> -57200000
A10: JUNIO | B10: =SUM('Base Inversionistas'!O5:O268) -> 34625000 | C10: 45 | E10: JUNIO | F10: -65400000 | H10: COSTA RICA | J10: -4620900 | U10: =SUM(I10:S10) -> -4620900
A11: JULIO | B11: =SUM('Base Inversionistas'!P5:P268) -> 47793000 | C11: 70 | E11: JULIO | F11: -43124340 | H11: CUBA | I11: -1477000 | S11: -1400000 | U11: =SUM(I11:S11) -> -2877000
A12: AGOSTO | B12: =SUM('Base Inversionistas'!Q5:Q268) -> 55225000 | C12: 68 | E12: AGOSTO | F12: -35013740 | H12: DEUDA FONDO | I12: -3000000 | J12: -3000000 | K12: -3000000 | L12: -3000000 | M12: -3000000 | N12: -3000000 | O12: -3000000 | P12: -3000000 | Q12: -3000000 | R12: -3000000 | S12: -3000000 | T12: -3000000 | U12: =SUM(I12:S12) -> -33000000
A13: SEPTIEMBRE | B13: =SUM('Base Inversionistas'!R5:R268) -> 63734000 | C13: 70 | E13: SEPTIEMBRE | F13: -14334120 | H13: EAV | L13: -12015000 | M13: -4229600 | P13: -11190450 | U13: =SUM(I13:S13) -> -27435050
A14: OCTUBRE | B14: ='Base Inversionistas'!S297 -> 70300000 | C14: =COUNTIF('Base Inversionistas'!S5:S268, ">0") -> 80 | E14: OCTUBRE | F14: =Gastos!T75 -> -62520903 | H14: INVERSIONISTAS | L14: -769900 | S14: -41900 | T14: -34200 | U14: =SUM(I14:S14) -> -811800
A15: NOVIEMBRE | B15: ='Base Inversionistas'!T297 -> 92819059 | C15: =COUNTIF('Base Inversionistas'!T5:T296, ">0") -> 130 | E15: NOVIEMBRE | F15: =Gastos!U75 -> -13131740 | H15: IVPT | M15: -22131200 | U15: =SUM(I15:S15) -> -22131200
A16: DICIEMBRE | B16: ='Base Inversionistas'!U297 -> 93925000 | C16: =COUNTIF('Base Inversionistas'!U6:U296, ">0") -> 140 | E16: DICIEMBRE | F16: =Gastos!V75 -> -67827550 | H16: JULIO S | P16: -3844290 | Q16: -2284620 | U16: =SUM(I16:S16) -> -6128910
A17: TOTALES | B17: =SUM(B4:B16) -> 740341909 | E17: TOTALES | F17: =SUM(F4:F16) -> -531593755 | H17: OFRENDA | K17: -3946000 | L17: -2000000 | O17: -2600000 | P17: -2375000 | R17: -1561973 | U17: =SUM(I17:S17) -> -12482973
A18: SALDO INVERSIONISTAS | B18: =B17+F17 -> 208748154 | H18: PAC | I18: -2700000 | J18: -5167500 | U18: =SUM(I18:S18) -> -7867500
H19: PANAMA | N19: -8000000 | O19: -1000000 | P19: -2100000 | R19: -7900000 | T19: -1000000 | U19: =SUM(I19:S19) -> -19000000
H20: PEDRO D | K20: -31000000 | L20: -31000000 | N20: -41400000 | O20: -20350000 | P20: -12045000 | R20: -29998000 | T20: -60793350 | U20: =SUM(I20:S20) -> -165793000
H21: VUELOS | N21: -5000000 | O21: -11174340 | P21: -459000 | Q21: -5849500 | R21: -4060930 | S21: -8689840 | U21: =SUM(I21:S21) -> -35233610
D22: =B16/A25 -> 234.8125 | H22: VALLEDUPAR | T22: -2000000 | U22: =SUM(I22:T22) -> -2000000
H23: Total general | I23: -12177000 | J23: -17788400 | K23: -42946000 | L23: -54376900 | M23: -34360800 | N23: -65400000 | O23: -43124340 | P23: -35013740 | Q23: -14334120 | R23: -62520903 | S23: -13131740 | T23: -67827550
A25: 400000
A26: Etiquetas de fila | B26: Cuenta de Cuotas_Enteras
A27: ANTIOQUIA | B27: 1
A28: Armenia | B28: 2
A29: Barranquilla | B29: 3
A30: Bayunca | B30: 2
A31: BOGOTA | B31: 38
A32: Bolivar | B32: 2
A33: Bucaramanga | B33: 5
A34: CALI | B34: 2
A35: CARTAGENA | B35: 6
A36: Cartago | B36: 1
A37: CERETÉ | B37: 3
A38: CHIGORODO | B38: 1
... A94: Total general | B94: 292

Sheet Base Inversionistas 26
J3: 2026
A4: NO. | B4: NOMBRES | C4: NO. IDENTIFICACION | D4: NO. CELULAR | E4: LOCALIDAD | F4: No. Cuotas | G4: SALDO A DIC2024 | H4: FORMA | I4: TIPO DE MOVIMIENTO | J4: ENERO | K4: FEBRERO | L4: MARZO | M4: ABRIL | N4: MAYO | O4: JUNIO | P4: JULIO | Q4: AGOSTO | R4: SEPTIEMBRE | S4: OCTUBRE | T4: NOVIEMBRE | U4: DICIEMBRE | V4: Total_Aportes | W4: Cuotas_Calculadas | X4: Meses_Con_Aporte | Y4: Cuotas_Enteras
A5: 1 | B5: ABNER GONZALEZ | C5: 9289920 | E5: Medellin | F5: 1 | G5: 2059000 | H5: BCOL AHO | I5: CREDITO | J5: 0 | K5: 0 | L5: 0 | M5: 0 | N5: 0 | O5: 0 | P5: 0 | Q5: 0 | R5: 0 | V5: =SUM(J5:U5) -> 0 | W5: =V5/400000 -> 0 | X5: =COUNTIF(J5:U5,">0") -> 0 | Y5: =ROUNDUP(W5,0) -> 0
A6: 2 | B6: ALBA MARINA ROMERO | G6: 100000 | I6: CREDITO | J6: 0 | K6: 0 | L6: 0 | M6: 0 | N6: 0 | O6: 0 | P6: 0 | Q6: 0 | R6: 0 | V6: =SUM(J6:U6) -> 0 | W6: =V6/400000 -> 0 | X6: =COUNTIF(J6:U6,">0") -> 0 | Y6: =ROUNDUP(W6,0) -> 0
A7: 3 | B7: ANA MISAD | E7: BOGOTA | G7: 200000 | H7: EFECTIVO | I7: CREDITO | J7: 0 | K7: 0 | L7: 0 | M7: 0 | N7: 0 | O7: 0 | P7: 0 | Q7: 0 | R7: 0 | V7: =SUM(J7:U7) -> 0 | W7: =V7/400000 -> 0 | X7: =COUNTIF(J7:U7,">0") -> 0 | Y7: =ROUNDUP(W7,0) -> 0
A8: 4 | B8: ANA CORTES | E8: BOGOTA | G8: 100000 | H8: EFECTIVO | I8: CREDITO | J8: 0 | K8: 0 | L8: 0 | M8: 0 | N8: 0 | O8: 0 | P8: 0 | Q8: 0 | R8: 0 | V8: =SUM(J8:U8) -> 0 | W8: =V8/400000 -> 0 | X8: =COUNTIF(J8:U8,">0") -> 0 | Y8: =ROUNDUP(W8,0) -> 0
A9: 5 | B9: ANA MARIA PORTILLA CLAROS | C9: 1114621012 | D9: 3207945735 | E9: BOGOTA | G9: 2000000 | H9: BCOL AHO | I9: CREDITO | J9: 0 | K9: 0 | L9: 0 | M9: 600000 | N9: 0 | O9: 0 | P9: 0 | Q9: 0 | R9: 0 | V9: =SUM(J9:U9) -> 600000 | W9: =V9/400000 -> 1.5 | X9: =COUNTIF(J9:U9,">0") -> 1 | Y9: =ROUNDUP(W9,0) -> 2
A10: 6 | B10: ANDRES CASTRILLON "GIRARDOTA" | C10: 1035855590 | D10: 3154949282 | E10: Girardota | G10: 1100000 | H10: BCOL AHO | I10: CREDITO | J10: 400000 | K10: 400000 | L10: 400000 | M10: 400000 | N10: 0 | O10: 400000 | P10: 0 | Q10: 0 | R10: 0 | V10: =SUM(J10:U10) -> 2000000 | W10: =V10/400000 -> 5 | X10: =COUNTIF(J10:U10,">0") -> 5 | Y10: =ROUNDUP(W10,0) -> 5
A11: 7 | B11: ANDRES MORENO ARRIAGA | C11: 1077465696 | D11: 3207593131 | E11: QUIBDO | G11: 1600000 | I11: CREDITO | J11: 0 | K11: 0 | L11: 0 | M11: 400000 | N11: 0 | O11: 800000 | P11: 0 | Q11: 0 | R11: 400000 | V11: =SUM(J11:U11) -> 1600000 | W11: =V11/400000 -> 4 | X11: =COUNTIF(J11:U11,">0") -> 3 | Y11: =ROUNDUP(W11,0) -> 4
A12: 8 | B12: ANGIE FINO | G12: 1000000 | I12: CREDITO | J12: 0 | K12: 0 | L12: 0 | M12: 0 | N12: 0 | O12: 0 | P12: 0 | Q12: 0 | R12: 0 | V12: =SUM(J12:U12) -> 0 | W12: =V12/400000 -> 0 | X12: =COUNTIF(J12:U12,">0") -> 0 | Y12: =ROUNDUP(W12,0) -> 0
A13: 9 | B13: ANONIMO | E13: BOGOTA | G13: 580000 | I13: CREDITO | J13: 0 | K13: 0 | L13: 0 | M13: 0 | N13: 0 | O13: 400000 | P13: 0 | Q13: 0 | R13: 0 | V13: =SUM(J13:U13) -> 400000 | W13: =V13/400000 -> 1 | X13: =COUNTIF(J13:U13,">0") -> 1 | Y13: =ROUNDUP(W13,0) -> 1
A14: 10 | B14: APOYO CASA PAC | G14: 0 | H14: BCOL AHO | I14: DEBITO | J14: 0 | K14: 0 | L14: 0 | M14: 0 | N14: 0 | O14: 0 | P14: 0 | Q14: 0 | R14: 0 | V14: =SUM(J14:U14) -> 0 | W14: =V14/400000 -> 0 | X14: =COUNTIF(J14:U14,">0") -> 0 | Y14: =ROUNDUP(W14,0) -> 0
A15: 11 | B15: BENITO HERRRA | E15: PTO. COLOM | F15: 3 | G15: 1600000 | H15: BCOL AHO | I15: CREDITO | J15: 0 | K15: 0 | L15: 0 | M15: 1600000 | N15: 0 | O15: 1200000 | P15: 1600000 | Q15: 0 | R15: 0 | V15: =SUM(J15:U15) -> 4400000 | W15: =V15/400000 -> 11 | X15: =COUNTIF(J15:U15,">0") -> 3 | Y15: =ROUNDUP(W15,0) -> 11
A16: 12 | B16: BIBIANA MONTOYA RODAS | G16: 1500000 | H16: BCOL AHO | I16: CREDITO | J16: 0 | K16: 0 | L16: 0 | M16: 0 | N16: 0 | O16: 0 | P16: 0 | Q16: 0 | R16: 0 | V16: =SUM(J16:U16) -> 0 | W16: =V16/400000 -> 0 | X16: =COUNTIF(J16:U16,">0") -> 0 | Y16: =ROUNDUP(W16,0) -> 0
A17: 13 | B17: BRAYER ALEXIS QUINTERO FERNANDEZ | C17: 1090395092 | E17: CUCUTA | G17: 2820000 | H17: BCOL AHO | I17: CREDITO | J17: 400000 | K17: 400000 | L17: 0 | M17: 1200000 | N17: 0 | O17: 400000 | P17: 400000 | Q17: 0 | R17: 0 | V17: =SUM(J17:U17) -> 2800000 | W17: =V17/400000 -> 7 | X17: =COUNTIF(J17:U17,">0") -> 5 | Y17: =ROUNDUP(W17,0) -> 7
A18: 14 | B18: CARLIS MICHELE PEREZ CANO | C18: 1095846194 | D18: 3022962452 | E18: BOGOTA | G18: 1000000 | H18: BCOL AHO | I18: CREDITO | J18: 400000 | K18: 400000 | L18: 0 | M18: 0 | N18: 0 | O18: 0 | P18: 0 | Q18: 0 | R18: 0 | V18: =SUM(J18:U18) -> 800000 | W18: =V18/400000 -> 2 | X18: =COUNTIF(J18:U18,">0") -> 2 | Y18: =ROUNDUP(W18,0) -> 2
A19: 15 | B19: CARLOS CARRASCO | E19: BOGOTA | F19: 1 | G19: 6219000 | H19: EFECTIVO | I19: CREDITO | J19: 400000 | K19: 400000 | L19: 400000 | M19: 400000 | N19: 400000 | O19: 600000 | P19: 0 | Q19: 400000 | R19: 400000 | V19: =SUM(J19:U19) -> 3400000 | W19: =V19/400000 -> 8.5 | X19: =COUNTIF(J19:U19,">0") -> 8 | Y19: =ROUNDUP(W19,0) -> 9
A20: 16 | B20: CARLOS PALMA | E20: BOGOTA | F20: 1 | G20: 4800000 | H20: EFECTIVO | I20: CREDITO | J20: 0 | K20: 800000 | L20: 400000 | M20: 400000 | N20: 400000 | O20: 0 | P20: 0 | Q20: 800000 | R20: 800000 | V20: =SUM(J20:U20) -> 3600000 | W20: =V20/400000 -> 9 | X20: =COUNTIF(J20:U20,">0") -> 6 | Y20: =ROUNDUP(W20,0) -> 9
A21: 17 | B21: CARLOS ANDRES COCUY | C21: 14797460 | D21: 3160438302 | E21: DOSQUEBRADAS | G21: 5200000 | H21: BCOL AHO | I21: CREDITO | J21: 450000 | K21: 450000 | L21: 500000 | M21: 600000 | N21: 0 | O21: 0 | P21: 600000 | Q21: 400000 | R21: 400000 | V21: =SUM(J21:U21) -> 3400000 | W21: =V21/400000 -> 8.5 | X21: =COUNTIF(J21:U21,">0") -> 7 | Y21: =ROUNDUP(W21,0) -> 9
A22: 18 | B22: CAROLINA QUIROGA | E22: BOGOTA | G22: 100000 | H22: BCOL AHO | I22: CREDITO | J22: 0 | K22: 0 | L22: 0 | M22: 400000 | N22: 400000 | O22: 0 | P22: 0 | Q22: 0 | R22: 0 | V22: =SUM(J22:U22) -> 800000 | W22: =V22/400000 -> 2 | X22: =COUNTIF(J22:U22,">0") -> 2 | Y22: =ROUNDUP(W22,0) -> 2
A23: 19 | B23: CESAR VERA | C23: 79333423 | D23: 3166268412 | E23: BOGOTA | F23: 3 | G23: 22900000 | H23: EFECTIVO | I23: CREDITO | J23: 2000000 | K23: 1600000 | L23: 1600000 | M23: 2000000 | N23: 800000 | O23: 4000000 | P23: 3100000 | Q23: 2400000 | R23: 800000 | V23: =SUM(J23:U23) -> 18300000 | W23: =V23/400000 -> 45.75 | X23: =COUNTIF(J23:U23,">0") -> 9 | Y23: =ROUNDUP(W23,0) -> 46
A24: 20 | B24: CLAUDIA ARCINIEGAS | E24: CUCUTA | G24: 800000 | H24: BCOL AHO | I24: CREDITO | J24: 0 | K24: 0 | L24: 0 | M24: 0 | N24: 400000 | O24: 0 | P24: 0 | Q24: 0 | R24: 0 | V24: =SUM(J24:U24) -> 400000 | W24: =V24/400000 -> 1 | X24: =COUNTIF(J24:U24,">0") -> 1 | Y24: =ROUNDUP(W24,0) -> 1
A25: 21 | B25: DANIEL VARGAS | E25: Neiva | F25: 1 | G25: 1200000 | H25: BCOL AHO | I25: CREDITO | J25: 400000 | K25: 600000 | L25: 600000 | M25: 0 | N25: 800000 | O25: 400000 | P25: 0 | Q25: 0 | R25: 0 | V25: =SUM(J25:U25) -> 2800000 | W25: =V25/400000 -> 7 | X25: =COUNTIF(J25:U25,">0") -> 5 | Y25: =ROUNDUP(W25,0) -> 7
A26: 22 | B26: DANIELA CASTO | G26: 200000 | H26: BCOL AHO | I26: CREDITO | J26: 0 | K26: 0 | L26: 0 | M26: 0 | N26: 0 | O26: 0 | P26: 0 | Q26: 0 | R26: 0 | V26: =SUM(J26:U26) -> 0 | W26: =V26/400000 -> 0 | X26: =COUNTIF(J26:U26,">0") -> 0 | Y26: =ROUNDUP(W26,0) -> 0
A27: 23 | B27: DAVID MAESTRE | G27: 2400000 | H27: BCOL AHO | I27: CREDITO | J27: 0 | K27: 0 | L27: 0 | M27: 0 | N27: 0 | O27: 0 | P27: 0 | Q27: 0 | R27: 0 | V27: =SUM(J27:U27) -> 0 | W27: =V27/400000 -> 0 | X27: =COUNTIF(J27:U27,">0") -> 0 | Y27: =ROUNDUP(W27,0) -> 0
A28: 24 | B28: DAVID MIRANDA | E28: BOGOTA | F28: 1 | G28: 4400000 | H28: BCOL AHO | I28: CREDITO | J28: 400000 | K28: 0 | L28: 0 | M28: 800000 | N28: 400000 | O28: 0 | P28: 1200000 | Q28: 0 | R28: 0 | V28: =SUM(J28:U28) -> 2800000 | W28: =V28/400000 -> 7 | X28: =COUNTIF(J28:U28,">0") -> 4 | Y28: =ROUNDUP(W28,0) -> 7
A29: 25 | B29: EDDWARD GARCIA | E29: BOGOTA | F29: 1 | G29: 240000 | H29: EFECTIVO | I29: CREDITO | J29: 0 | K29: 0 | L29: 0 | M29: 0 | N29: 0 | O29: 0 | P29: 0 | Q29: 0 | R29: 0 | V29: =SUM(J29:U29) -> 0 | W29: =V29/400000 -> 0 | X29: =COUNTIF(J29:U29,">0") -> 0 | Y29: =ROUNDUP(W29,0) -> 0
A30: 26 | B30: ERICA PLATA | C30: 60362206 | D30: 3165652640 | E30: LOS PATIOS | F30: 1 | G30: 1000000 | H30: BCOL AHO 2 | I30: CREDITO | J30: 0 | K30: 400000 | L30: 400000 | M30: 400000 | N30: 400000 | O30: 0 | P30: 0 | Q30: 0 | R30: 401000 | V30: =SUM(J30:U30) -> 2001000 | W30: =V30/400000 -> 5.0025 | X30: =COUNTIF(J30:U30,">0") -> 5 | Y30: =ROUNDUP(W30,0) -> 6
A31: 27 | B31: ERMILGEN RIAÑO | E31: BOGOTA | G31: 100000 | H31: EFECTIVO | I31: CREDITO | J31: 0 | K31: 0 | L31: 0 | M31: 0 | N31: 0 | O31: 0 | P31: 0 | Q31: 0 | R31: 0 | V31: =SUM(J31:U31) -> 0 | W31: =V31/400000 -> 0 | X31: =COUNTIF(J31:U31,">0") -> 0 | Y31: =ROUNDUP(W31,0) -> 0
A32: 28 | B32: ESTEBAN ISAZA MUÑOZ | C32: 88230239 | D32: 3123933769 | E32: PAMPLONA | F32: 1 | G32: 10045000 | H32: BCOL AHO 2 | I32: CREDITO | J32: 1600000 | K32: 1600000 | L32: 1400000 | M32: 1200000 | N32: 1200000 | O32: 1200000 | P32: 1200000 | Q32: 1200000 | R32: 1200000 | V32: =SUM(J32:U32) -> 11800000 | W32: =V32/400000 -> 29.5 | X32: =COUNTIF(J32:U32,">0") -> 9 | Y32: =ROUNDUP(W32,0) -> 30
A33: 29 | B33: ESTHER TORRES | E33: BOGOTA | G33: 450000 | H33: EFECTIVO | I33: CREDITO | J33: 0 | K33: 0 | L33: 0 | M33: 0 | N33: 0 | O33: 0 | P33: 0 | Q33: 0 | R33: 0 | V33: =SUM(J33:U33) -> 0 | W33: =V33/400000 -> 0 | X33: =COUNTIF(J33:U33,">0") -> 0 | Y33: =ROUNDUP(W33,0) -> 0
A34: 30 | B34: EUSEBIO MONTES | F34: 1 | G34: 0 | H34: No Registra | I34: CREDITO | J34: 0 | K34: 0 | L34: 0 | M34: 0 | N34: 0 | O34: 0 | P34: 0 | Q34: 0 | R34: 0 | V34: =SUM(J34:U34) -> 0 | W34: =V34/400000 -> 0 | X34: =COUNTIF(J34:U34,">0") -> 0 | Y34: =ROUNDUP(W34,0) -> 0
A35: 31 | B35: FLOR ACUÑA | E35: BOGOTA | G35: 400000 | H35: BCOL AHO | I35: CREDITO | J35: 0 | K35: 0 | L35: 0 | M35: 0 | N35: 0 | O35: 0 | P35: 0 | Q35: 0 | R35: 0 | V35: =SUM(J35:U35) -> 0 | W35: =V35/400000 -> 0 | X35: =COUNTIF(J35:U35,">0") -> 0 | Y35: =ROUNDUP(W35,0) -> 0
A36: 32 | B36: FLOR SALAMANCA | C36: 23963745 | D36: 3142385522 | E36: BOGOTA | F36: 2 | G36: 21600000 | H36: BCOL AHO-EF | I36: CREDITO | J36: 3600000 | K36: 3600000 | L36: 3600000 | M36: 5600000 | N36: 3600000 | O36: 3600000 | P36: 3600000 | Q36: 3600000 | R36: 4000000 | V36: =SUM(J36:U36) -> 34800000 | W36: =V36/400000 -> 87 | X36: =COUNTIF(J36:U36,">0") -> 9 | Y36: =ROUNDUP(W36,0) -> 87
A37: 33 | B37: FRANCISCO VILLAMIL | E37: BOGOTA | G37: 2200000 | H37: EFECTIVO | I37: CREDITO | J37: 400000 | K37: 400000 | L37: 400000 | M37: 400000 | N37: 400000 | O37: 400000 | P37: 400000 | Q37: 400000 | R37: 400000 | V37: =SUM(J37:U37) -> 3600000 | W37: =V37/400000 -> 9 | X37: =COUNTIF(J37:U37,">0") -> 9 | Y37: =ROUNDUP(W37,0) -> 9
A38: 34 | B38: FREIMAN JAIMES | C38: 13177594 | D38: 3107951023 | E38: OCAÑA | F38: 1 | G38: 800000 | H38: No Registra | I38: CREDITO | J38: 0 | K38: 0 | L38: 400000 | M38: 0 | N38: 400000 | O38: 0 | P38: 800000 | Q38: 400000 | R38: 600000 | V38: =SUM(J38:U38) -> 2600000 | W38: =V38/400000 -> 6.5 | X38: =COUNTIF(J38:U38,">0") -> 5 | Y38: =ROUNDUP(W38,0) -> 7
A39: 35 | B39: GISEL DANIELA GUTIERREZ MURILLO | G39: 1200000 | H39: BCOL AHO | I39: CREDITO | J39: 0 | K39: 0 | L39: 0 | M39: 0 | N39: 0 | O39: 0 | P39: 0 | Q39: 0 | R39: 0 | V39: =SUM(J39:U39) -> 0 | W39: =V39/400000 -> 0 | X39: =COUNTIF(J39:U39,">0") -> 0 | Y39: =ROUNDUP(W39,0) -> 0
A40: 36 | B40: GUILLERMO MONSALVE | C40: 4803428 | D40: 3009838761 | E40: SINCELEJO | G40: 4400000 | H40: BCOL AHO | I40: CREDITO | J40: 0 | K40: 1600000 | L40: 1600000 | M40: 0 | N40: 1600000 | O40: 1600000 | P40: 1600000 | Q40: 1600000 | R40: 1600000 | V40: =SUM(J40:U40) -> 11200000 | W40: =V40/400000 -> 28 | X40: =COUNTIF(J40:U40,">0") -> 7 | Y40: =ROUNDUP(W40,0) -> 28
A41: 37 | B41: HERMES PATIÑO | C41: 93206783 | D41: 3125188563 | E41: SINCELEJO | G41: 6000000 | H41: BCOL AHO | I41: CREDITO | J41: 0 | K41: 800000 | L41: 800000 | M41: 0 | N41: 0 | O41: 800000 | P41: 800000 | Q41: 800000 | R41: 800000 | V41: =SUM(J41:U41) -> 4800000 | W41: =V41/400000 -> 12 | X41: =COUNTIF(J41:U41,">0") -> 6 | Y41: =ROUNDUP(W41,0) -> 12
A42: 38 | B42: HUMBERTO OSPINO | C42: 72147202 | D42: 3126317467 | E42: ENVIGADO | G42: 4400000 | H42: BCOL AHO 2 | I42: CREDITO | J42: 0 | K42: 0 | L42: 0 | M42: 400000 | N42: 0 | O42: 0 | P42: 0 | Q42: 1600000 | R42: 0 | V42: =SUM(J42:U42) -> 2000000 | W42: =V42/400000 -> 5 | X42: =COUNTIF(J42:U42,">0") -> 2 | Y42: =ROUNDUP(W42,0) -> 5
...

Sheet Gastos 26
A4: NO. | B4: CLASIF | C4: NOMBRES | D4: NO. IDENTIFICACION | E4: NO. CELULAR | F4: LOCALIDAD | G4: No. Cuotas | H4: SALDO A DIC2024 | I4: FORMA | J4: TIPO DE MOVIMIENTO | K4: ENERO | L4: FEBRERO | M4: MARZO | N4: ABRIL | O4: MAYO | P4: JUNIO | Q4: JULIO | R4: AGOSTO | S4: SEPTIEMBRE | T4: OCTUBRE | U4: NOVIEMBRE | V4: DICIEMBRE | W4: ENERO
A5: 1 | B5: OFRENDA | C5: OFRENDA JORGE LUIS BARRIOS | J5: DEBITO
A6: =A5+1 -> 2 | B6: DEUDA FONDO | C6: DEUDA COLPORTAJE | J6: DEBITO | K6: -6498740
A7: =A6+1 -> 3 | B7: PAC | C7: APOYO CASA PAC | H7: -12000000 | J7: DEBITO
A8: =A7+1 -> 4 | B8: PAC | C8: APOYO CASA PAC | H8: -5231807 | I8: BCOL AHO | J8: DEBITO
A9: =A8+1 -> 5 | B9: PAC | C9: APOYO CASA PAC | H9: -3500000 | I9: BCOL ALHO | J9: DEBITO
A10: =A9+1 -> 6 | B10: CEPEV | C10: APOYO CEPPEV | H10: 0 | I10: BCOL AHO | J10: DEBITO
A11: =A10+1 -> 7 | B11: BRASIL | C11: APOYO HNOS. EN BRASIL | H11: -20000000 | I11: BCOL AHO | J11: DEBITO
A12: =A11+1 -> 8 | B12: PAC | C12: APOYO PERU PAC | J12: DEBITO
A13: =A12+1 -> 9 | B13: PAC | C13: ARRIENDO CASA PAC | H13: 0 | I13: BCOL CTE | J13: DEBITO
A14: =A13+1 -> 10 | B14: PAC | C14: ARRIENDO CASA PAC | H14: 0 | J14: DEBITO
A15: =A14+1 -> 11 | B15: INVERSIONISTAS | C15: COMPRA CELULAR | H15: -6700000 | I15: BCOL AHO | J15: DEBITO
A16: =A15+1 -> 12 | B16: PEDRO D | C16: ENTREGA RESERVA PEDRO DONG | J16: DEBITO
A17: =A16+1 -> 13 | B17: EAV | C17: ENVIO EAV | H17: -12300000 | J17: DEBITO
A18: =A17+1 -> 14 | B18: COSTA RICA | C18: OBRA COSTA RICA | J18: DEBITO
A19: =A18+1 -> 15 | B19: OFRENDA | C19: OFRENDA A JONES COSTA | H19: -400000 | I19: BCOL AHO | J19: DEBITO
A20: =A19+1 -> 16 | B20: PAC | C20: PAGO DEUDA ARRIENDO PAC | H20: 0 | I20: BCOL AHO | J20: DEBITO
A21: =A20+1 -> 17 | B21: CUBA | C21: VIATICOS CUBA | I21: BCOL AHO | J21: DEBITO
A22: =A21+1 -> 18 | B22: OFRENDA | C22: VIATICOS EUROPA DAVID MAESTRE | H22: -6413915 | J22: DEBITO
A23: =A22+1 -> 19 | B23: OFRENDA | C23: VIATICOS JONES | H23: 0 | I23: EFECTIVO | J23: DEBITO
A24: =A23+1 -> 20 | B24: EAV | C24: VIATICOS EAV DE RESERVA PEDRO D | I24: BCOL AHO | J24: DEBITO
A25: =A24+1 -> 21 | B25: IVPT | C25: GASTOS IVPT | H25: 0 | I25: BCOL AHO | J25: DEBITO
A26: =A25+1 -> 22 | B26: PANAMA | C26: ENTREGA A DAVID MAESTRE PANAMA | J26: DEBITO
A27: =A26+1 -> 23 | B27: VUELOS | C27: ENTREGA A DAVID M RESERVA PEDRO | J27: DEBITO
A28: =A27+1 -> 24 | B28: CEPEV | C28: APOYO CENA CEPPEV | J28: DEBITO
A29: =A28+1 -> 25 | B29: PEDRO D | C29: ENTREGA RESERVA PEDRO DONG | J29: DEBITO
A30: =A29+1 -> 26 | B30: PANAMA | C30: APOYO PAC PANAMA | J30: DEBITO
A31: =A30+1 -> 27 | B31: VUELOS | C31: ENTREGA DAVID MIRANDA RESERVA PD | J31: DEBITO
A32: =A31+1 -> 28 | B32: VUELOS | C32: ENTREGA DAVID MIRANDA RESERVA PD | J32: DEBITO
A33: =A32+1 -> 29 | B33: PANAMA | C33: APOYO PAC PANAMA | J33: DEBITO
A34: =A33+1 -> 30 | B34: PEDRO D | C34: ENTREGA RESERVA PEDRO DONG | J34: DEBITO
A35: =A34+1 -> 31 | B35: PANAMA | C35: LUIS MIGUEL NARANJO APOYO PANAMA | J35: DEBITO
A36: =A35+1 -> 32 | B36: VUELOS | C36: VIATICOS COLPORTORES | J36: DEBITO
A37: =A36+1 -> 33 | B37: OFRENDA | C37: APOYO LUIS GABRIEL BRASIL | J37: DEBITO
... A54: =A53+1 -> 50 | B54: PANAMA | C54: LUIS MIGUEL NARANJO APOYO PANAMA | J54: DEBITO
A55: 51 | B55: CUBA | C55: APOYO CUBA | J55: DEBITO
A56: 52 | B56: INVERSIONISTAS | C56: MOVIL INVERSIONISTAS | J56: DEBITO
A57: 53 | B57: VUELOS | C57: DAVID MIRANDA VUELOS COLPORTORES | J57: DEBITO
A58: 54 | B58: INVERSIONISTAS | C58: MOVIL INVERSIONISTAS | J58: DEBITO | K58: -100800
A59: 55 | B59: PANAMA | C59: LUIS MIGUEL NARANJO APOYO PANAMA | J59: DEBITO
...

Sheet Resumen 2026
A1: INDICADORES CLAVE
I2: OCT | J2: NOV | K2: DIC | L2: ENE | M2: FEB | N2: MAR | O2: ABR | P2: MAY
A3: MES | B3: TOTAL APORTES | C3: INVERSIONISTAS ACTIVOS | E3: MES | F3: TOTAL GASTOS | H3: NUEVOS INV (OCT) | I3: =COUNTIFS('Base Inversionistas'!R4:R267, "=0", 'Base Inversionistas'!S4:S267, ">0") -> 34 | J3: =COUNTIFS('Base Inversionistas'!S5:S296, "=0", 'Base Inversionistas'!T5:T296, ">0") -> 81 | K3: =COUNTIFS('Base Inversionistas'!T5:T296, "=0", 'Base Inversionistas'!U5:U296, ">0") -> 39 | L3: =COUNTIFS('Base Inversionistas'!U5:U296, "= 0", 'Base Inversionistas 26'!J5:J400, ">0") -> #VALUE! | M3: =COUNTIFS('Base Inversionistas 26'!J5:J400, "=0", 'Base Inversionistas 26'!K5:K400, ">0") -> 45 | N3: =COUNTIFS('Base Inversionistas 26'!K5:K400, "=0", 'Base Inversionistas 26'!L5:L400, ">0") -> 31 | O3: =COUNTIFS('Base Inversionistas 26'!L5:L400, "=0", 'Base Inversionistas 26'!M5:M400, ">0") -> 53 | P3: =COUNTIFS('Base Inversionistas 26'!M5:M400, "=0", 'Base Inversionistas 26'!N5:N400, ">0") -> 41 | Q3: =COUNTIFS('Base Inversionistas 26'!N5:N400, "=0", 'Base Inversionistas 26'!O5:O400, ">0") -> 55 | R3: =COUNTIFS('Base Inversionistas 26'!O5:O400, "=0", 'Base Inversionistas 26'!P5:P400, ">0") -> 41
A4: 2025 | B4: ='Resumen 2025'!B17 -> 740341909 | E4: 2025 | F4: ='Resumen 2025'!F17 -> -531593755 | H4: BAJAS INV | I4: =COUNTIFS('Base Inversionistas'!R4:R267, ">0", 'Base Inversionistas'!S4:S267, "=0") -> 24 | J4: =COUNTIFS('Base Inversionistas'!S4:S296, ">0", 'Base Inversionistas'!T4:T296, "=0") -> 31 | K4: =COUNTIFS('Base Inversionistas'!T4:T296, ">0", 'Base Inversionistas'!U4:U296, "=0") -> 29 | L4: =COUNTIFS('Base Inversionistas'!U4:U296, ">0", 'Base Inversionistas'!V4:V296, "=0") -> 90 | M4: =COUNTIFS('Base Inversionistas 26'!J5:J400, "> 0", 'Base Inversionistas 26'!K5:K400, "=0") -> 33 | N4: =COUNTIFS('Base Inversionistas 26'!K5:K400, "> 0", 'Base Inversionistas 26'!L5:L400, "=0") -> 35 | O4: =COUNTIFS('Base Inversionistas 26'!L5:L400, "> 0", 'Base Inversionistas 26'!M5:M400, "=0") -> 38 | P4: =COUNTIFS('Base Inversionistas 26'!M5:M400, "> 0", 'Base Inversionistas 26'!N5:N400, "=0") -> 68 | Q4: =COUNTIFS('Base Inversionistas 26'!N5:N400, "> 0", 'Base Inversionistas 26'!O5:O400, "=0") -> 35 | R4: =COUNTIFS('Base Inversionistas 26'!O5:O400, "> 0", 'Base Inversionistas 26'!P5:P400, "=0") -> 46
A5: ENERO | B5: ='Base Inversionistas 26'!J401 -> 97408000 | C5: =COUNTIF('Base Inversionistas 26'!J5:J400,">0") -> 107 | E5: ENERO | F5: ='Gastos 26'!K123 -> -14223540
A6: FEBRERO | B6: ='Base Inversionistas 26'!K401 -> 121440243 | C6: =COUNTIF('Base Inversionistas 26'!J5:K400,">0") -> 226 | E6: FEBRERO | F6: ='Gastos 26'!L123 -> -90677381
A7: MARZO | B7: ='Base Inversionistas 26'!L401 -> 102625000 | C7: =COUNTIF('Base Inversionistas 26'!L5:L400,">0") -> 115 | E7: MARZO | F7: ='Gastos 26'!M123 -> -53757023 | H7: CLASIFICACION GASTOS | I7: Suma de ENERO | J7: Suma de FEBRERO | K7: Suma de MARZO | L7: Suma de ABRIL | M7: Suma de MAYO | N7: Suma de JUNIO | O7: Suma de JULIO | P7: Suma de AGOSTO | Q7: Suma de SEPTIEMBRE | R7: Suma de OCTUBRE | S7: Suma de NOVIEMBRE | T7: Suma de DICIEMBRE | U7: TOTAL
A8: ABRIL | B8: ='Base Inversionistas 26'!M401 -> 112685982 | C8: =COUNTIF('Base Inversionistas 26'!M5:M400,">0") -> 130 | E8: ABRIL | F8: ='Gastos 26'!N123 -> -69816950 | H8: BRASIL | O8: -15487675 | P8: -5718695 | U8: =SUM(I8:S8) -> -21206370
A9: MAYO | B9: ='Base Inversionistas 26'!N401 -> 110994000 | C9: =COUNTIF('Base Inversionistas 26'!N6:N401,">0") -> 104 | E9: MAYO | F9: ='Gastos 26'!O123 -> -67382816 | H9: CEPEV | P9: -5000000 | U9: =SUM(I9:S9) -> -5000000
A10: JUNIO | B10: ='Base Inversionistas 26'!O401 -> 120764000 | C10: =COUNTIF('Base Inversionistas 26'!O6:O400,">0") -> 123 | E10: JUNIO | F10: ='Gastos 26'!P123 -> -75242944 | H10: COSTA RICA | U10: =SUM(I10:S10) -> 0
A11: JULIO | B11: ='Base Inversionistas 26'!P401 -> 130541664 | C11: =COUNTIF('Base Inversionistas 26'!P7:P400,">0") -> 118 | E11: JULIO | F11: ='Gastos 26'!Q123 -> -64915933 | H11: CUBA | I11: 0 | U11: =SUM(I11:S11) -> 0
A12: AGOSTO | B12: ='Base Inversionistas 26'!Q401 -> 127888500 | E12: AGOSTO | F12: ='Gastos 26'!R123 -> -109953072 | H12: DEUDA FONDO | I12: -6498740 | U12: =SUM(I12:S12) -> -6498740
A13: SEPTIEMBRE | B13: ='Base Inversionistas 26'!R401 -> 60271000 | E13: SEPTIEMBRE | F13: ='Gastos 26'!S123 -> -81248853 | H13: EAV | U13: =SUM(I13:S13) -> 0
A14: OCTUBRE | E14: OCTUBRE | H14: INVERSIONISTAS | I14: -100800 | J14: 0 | K14: -55800 | L14: -46300 | M14: -55300 | N14: -46300 | O14: -55300 | P14: -46300 | U14: =SUM(I14:S14) -> -406100
A15: NOVIEMBRE | E15: NOVIEMBRE | H15: IVPT | U15: =SUM(I15:S15) -> 0
A16: DICIEMBRE | E16: DICIEMBRE | H16: JULIO S | J16: 0 | U16: =SUM(I16:S16) -> 0
A17: TOTALES | B17: =SUM(B4:B16) -> 1724960298 | E17: TOTALES | F17: =SUM(F4:F16) -> -1158812267 | H17: OFRENDA | U17: =SUM(I17:S17) -> 0
A18: SALDO INVERSIONISTAS | B18: =B17+F17 -> 566148031 | H18: PAC | K18: -40000000 | U18: =SUM(I18:S18) -> -40000000
H19: PANAMA | I19: -7624000 | J19: -6176000 | K19: -6858000 | L19: -2000000 | N19: -28094702 | O19: -1000000 | P19: -9661190 | U19: =SUM(I19:S19) -> -61413892
H20: PEDRO D | J20: -60897000 | L20: -33600000 | M20: -67327516 | N20: -37882873 | O20: -41493250 | P20: -39128787 | U20: =SUM(I20:S20) -> -280329426
H21: VUELOS | J21: -23604381 | K21: -6843223 | L21: -28635650 | N21: -9219069 | O21: -1879708 | P21: -1861000 | U21: =SUM(I21:S21) -> -72043031
H22: VALLEDUPAR | U22: =SUM(I22:T22) -> 0
H23: Total general | I23: -14223540 | J23: -90677381 | K23: -53757023 | L23: -64281950 | M23: -67382816 | N23: -75242944 | O23: -59915933 | P23: -61415972
A25: 400000
A26: Etiquetas de fila | B26: Suma de Cuotas_Enteras | C26: Suma de ABRIL | D26: Suma de MAYO
A27: ANTIOQUIA | B27: 1 | C27: 50000 | D27: 50000
A28: Armenia | B28: 0 | C28: 0 | D28: 0
A29: Barranquilla | B29: 23 | C29: 0 | D29: 2540000
A30: Bayunca | B30: 4 | C30: 0 | D30: 400000
A31: BOGOTA | B31: 186 | C31: 16720000 | D31: 9760000
A32: Bolivar | B32: 6 | C32: 800000 | D32: 400000
A33: BUCARAMANGA | B33: 91 | C33: 6000000 | D33: 400000
A34: CALI | B34: 8 | C34: 400000 | D34: 0
A35: CARTAGENA | B35: 8 | C35: 0 | D35: 400000
A36: Cartago | B36: 18 | C36: 2400000 | D36: 500000
A37: CERETÉ | B37: 0 | C37: 0 | D37: 0
A38: CHIGORODO | B38: 1 | C38: 400000 | D38: 0
... A99: Total general | B99: 1284 | C99: 112685982 | D99: 67715000

Sheet XLOCALIDAD
B2: LOCALIDAD | C2: TOTAL DICIEMBRE | D2: Total Cuotas DICIEMBRE | G2: LOCALIDAD | H2: TOTAL CUOTAS 2025 | J2: LOCALIDAD | K2: TOTAL CUOTAS 2026 | L2: CUOTAS ABRIL | M2: CUOTAS MAYO
B3: VALLEDUPAR | C3: 14000000 | D3: =C3/400000 -> 35 | G3: BOGOTA | H3: 328 | J3: Armenia | K3: 0 | L3: 0 | M3: 0
B4: BOGOTA | C4: 10120000 | D4: =C4/400000 -> 25.3 | G4: VALLEDUPAR | H4: 170 | J4: Barranquilla | K4: 23 | L4: 0 | M4: 6.35
B5: LOS PATIOS | C5: 5000000 | D5: =C5/400000 -> 12.5 | G5: LOS PATIOS | H5: 70 | J5: Bayunca | K5: 4 | L5: 0 | M5: 1
B6: BOGOTA | C6: 4800000 | D6: =C6/400000 -> 12 | G6: BUCARAMANGA | H6: 67 | J6: BOGOTA | K6: 186 | L6: 41.8 | M6: 24.4
B7: CUCUTA | C7: 4700000 | D7: =C7/400000 -> 11.75 | G7: UBATE | H7: 62 | J7: Bolivar | K7: 6 | L7: 2 | M7: 1
B8: OCAÑA | C8: 3200000 | D8: =C8/400000 -> 8 | G8: CUCUTA | H8: 58 | J8: BUCARAMANGA | K8: 91 | L8: 15 | M8: 1
B9: UBATE | C9: 3200000 | D9: =C9/400000 -> 8 | G9: BARRANQUILLA | H9: 55 | J9: CARTAGENA | K9: 8 | L9: 0 | M9: 1
B10: GIRARDOTA | C10: 2800000 | D10: =C10/400000 -> 7 | G10: MEDELLIN | H10: 47 | J10: CERETÉ | K10: 0 | L10: 0 | M10: 0
B11: MONTERÍA | C11: 2800000 | D11: =C11/400000 -> 7 | G11: GIRARDOTA | H11: 43 | J11: CHIGORODO | K11: 1 | L11: 1 | M11: 0
B12: QUIBDO | C12: 2800000 | D12: =C12/400000 -> 7 | G12: CARTAGENA | H12: 40 | J12: CHIQUINQUIRA | K12: 25 | L12: 5 | M12: 5
B13: PUERTO COLOMBIA | C13: 2790000 | D13: =C13/400000 -> 6.975 | G13: PEREIRA | H13: 40 | J13: CUCUNUBA | K13: 0 | L13: 0 | M13: 0
B14: PAMPLONA | C14: 2690000 | D14: =C14/400000 -> 6.725 | G14: MONTERIA | H14: 39 | J14: CUCUTA | K14: 48 | L14: 13 | M14: 3
... B54: RIONEGRO | C54: 80000 | D54: =C54/400000 -> 0.2 | G54: CHIGORODO | H54: 4 | J54: Yopal | K54: 7 | L54: 2 | M54: 0
G55: CHOCO | H55: 4 | J55: Total general | K55: 1284 | L55: 281.71495 | M55: 169.2875
G56: VIOTA | H56: 3
G57: RIONEGRO | H57: 3
G58: SOGAMOSO | H58: 3
G59: CUCUNUBA | H59: 3
G60: La mina | H60: 3
G61: ZIPAQUIRA | H61: 2
G62: FUQUENE | H62: 2
G63: SUTATAUSA | H63: 2
G64: Riohacha | H64: 2
G65: SANTA LUCIA | H65: 2
G66: SAN JUAN | H66: 1
G67: ANTIOQUIA | H67: 1
G68: BELLO | H68: 1

Sheet Nuevos IDR Cepev
A2: Nombre | B2: Localidad | C2: Teléfono | D2: Cuota | E2: Monto
A3: Jonas quintero | B3: Bogotá | D3: 1
A4: Víctor peña | B4: Barranquilla | D4: 2
A5: Eusebio montes | B5: Barranquilla | D5: 1
A6: Carlos Peña | B6: Bucaramanga | D6: 1
A7: Juan Pablo Olivella | B7: Valledupar | D7: 2
A8: Rafael Gutiérrez | B8: Patios | D8: 1
A9: Adrián Hernández | B9: Girardota | D9: 1
A10: David delgado | B10: Patios | D10: 1.5
A11: Héctor Galeano | B11: Bogotá | D11: 2
A12: Sneider | B12: Villavicencio | D12: 1
A13: Daniel mota | B13: Villavicencio | D13: 1
A14: Iglesia en Villavicencio | B14: Villavicencio | D14: 1
... A56: Julio monsalve | B56: Medellín | D56: 0.5

Sheet Central_IDR
A1: NOMBRES | B1: NO. IDENTIFICACION | C1: NO. CELULAR | D1: LOCALIDAD | E1: ENERO | F1: FEBRERO | G1: MARZO | H1: ABRIL | I1: MAYO | J1: JUNIO | K1: JULIO | L1: AGOSTO | N1: 400000
A2: ALBA MARINA ROMERO | E2: ='[2]Base Inversionistas 26'!J5/$N$1 -> 0 | F2: ='[2]Base Inversionistas 26'!K5/$N$1 -> 0 | G2: ='[2]Base Inversionistas 26'!L5/$N$1 -> 0 | H2: ='[2]Base Inversionistas 26'!M5/$N$1 -> 0 | I2: ='[2]Base Inversionistas 26'!N5/$N$1 -> 0 | J2: ='[2]Base Inversionistas 26'!O5/$N$1 -> 0 | K2: ='[2]Base Inversionistas 26'!P5/$N$1 -> 0 | L2: ='[2]Base Inversionistas 26'!Q5/$N$1 -> 0
A3: ANA MISAD | D3: BOGOTA | E3: ='[2]Base Inversionistas 26'!J6/$N$1 -> 0 | F3: ='[2]Base Inversionistas 26'!K6/$N$1 -> 0 | G3: ='[2]Base Inversionistas 26'!L6/$N$1 -> 0 | H3: ='[2]Base Inversionistas 26'!M6/$N$1 -> 0 | I3: ='[2]Base Inversionistas 26'!N6/$N$1 -> 0 | J3: ='[2]Base Inversionistas 26'!O6/$N$1 -> 0 | K3: ='[2]Base Inversionistas 26'!P6/$N$1 -> 0 | L3: ='[2]Base Inversionistas 26'!Q6/$N$1 -> 0
A4: ANA CORTES | D4: BOGOTA | E4: ='[2]Base Inversionistas 26'!J7/$N$1 -> 0 | F4: ='[2]Base Inversionistas 26'!K7/$N$1 -> 0 | G4: ='[2]Base Inversionistas 26'!L7/$N$1 -> 0 | H4: ='[2]Base Inversionistas 26'!M7/$N$1 -> 0 | I4: ='[2]Base Inversionistas 26'!N7/$N$1 -> 0 | J4: ='[2]Base Inversionistas 26'!O7/$N$1 -> 0 | K4: ='[2]Base Inversionistas 26'!P7/$N$1 -> 0 | L4: ='[2]Base Inversionistas 26'!Q7/$N$1 -> 0
A5: ANA MARIA PORTILLA CLAROS | B5: 1114621012 | C5: 3207945735 | D5: BOGOTA | E5: ='[2]Base Inversionistas 26'!J8/$N$1 -> 0 | F5: ='[2]Base Inversionistas 26'!K8/$N$1 -> 0 | G5: ='[2]Base Inversionistas 26'!L8/$N$1 -> 0 | H5: ='[2]Base Inversionistas 26'!M8/$N$1 -> 1.5 | I5: ='[2]Base Inversionistas 26'!N8/$N$1 -> 0 | J5: ='[2]Base Inversionistas 26'!O8/$N$1 -> 0 | K5: ='[2]Base Inversionistas 26'!P8/$N$1 -> 0 | L5: ='[2]Base Inversionistas 26'!Q8/$N$1 -> 0
A6: ANDRES CASTRILLON "GIRARDOTA" | B6: 1035855590 | C6: 3154949282 | D6: Girardota | E6: ='[2]Base Inversionistas 26'!J9/$N$1 -> 1 | F6: ='[2]Base Inversionistas 26'!K9/$N$1 -> 1 | G6: ='[2]Base Inversionistas 26'!L9/$N$1 -> 1 | H6: ='[2]Base Inversionistas 26'!M9/$N$1 -> 1 | I6: ='[2]Base Inversionistas 26'!N9/$N$1 -> 0 | J6: ='[2]Base Inversionistas 26'!O9/$N$1 -> 1 | K6: ='[2]Base Inversionistas 26'!P9/$N$1 -> 0 | L6: ='[2]Base Inversionistas 26'!Q9/$N$1 -> 0
A7: ANDRES MORENO ARRIAGA | B7: 1077465696 | C7: 3207593131 | D7: QUIBDO | E7: ='[2]Base Inversionistas 26'!J10/$N$1 -> 0 | F7: ='[2]Base Inversionistas 26'!K10/$N$1 -> 0 | G7: ='[2]Base Inversionistas 26'!L10/$N$1 -> 0 | H7: ='[2]Base Inversionistas 26'!M10/$N$1 -> 1 | I7: ='[2]Base Inversionistas 26'!N10/$N$1 -> 0 | J7: ='[2]Base Inversionistas 26'!O10/$N$1 -> 2 | K7: ='[2]Base Inversionistas 26'!P10/$N$1 -> 0 | L7: ='[2]Base Inversionistas 26'!Q10/$N$1 -> 0
A8: ANGIE FINO | E8: ='[2]Base Inversionistas 26'!J11/$N$1 -> 0 | F8: ='[2]Base Inversionistas 26'!K11/$N$1 -> 0 | G8: ='[2]Base Inversionistas 26'!L11/$N$1 -> 0 | H8: ='[2]Base Inversionistas 26'!M11/$N$1 -> 0 | I8: ='[2]Base Inversionistas 26'!N11/$N$1 -> 0 | J8: ='[2]Base Inversionistas 26'!O11/$N$1 -> 0 | K8: ='[2]Base Inversionistas 26'!P11/$N$1 -> 0 | L8: ='[2]Base Inversionistas 26'!Q11/$N$1 -> 0
A9: ANONIMO | D9: BOGOTA | E9: ='[2]Base Inversionistas 26'!J12/$N$1 -> 0 | F9: ='[2]Base Inversionistas 26'!K12/$N$1 -> 0 | G9: ='[2]Base Inversionistas 26'!L12/$N$1 -> 0 | H9: ='[2]Base Inversionistas 26'!M12/$N$1 -> 0 | I9: ='[2]Base Inversionistas 26'!N12/$N$1 -> 0 | J9: ='[2]Base Inversionistas 26'!O12/$N$1 -> 1 | K9: ='[2]Base Inversionistas 26'!P12/$N$1 -> 0 | L9: ='[2]Base Inversionistas 26'!Q12/$N$1 -> 0
A10: APOYO CASA PAC | E10: ='[2]Base Inversionistas 26'!J13/$N$1 -> 0 | F10: ='[2]Base Inversionistas 26'!K13/$N$1 -> 0 | G10: ='[2]Base Inversionistas 26'!L13/$N$1 -> 0 | H10: ='[2]Base Inversionistas 26'!M13/$N$1 -> 0 | I10: ='[2]Base Inversionistas 26'!N13/$N$1 -> 0 | J10: ='[2]Base Inversionistas 26'!O13/$N$1 -> 0 | K10: ='[2]Base Inversionistas 26'!P13/$N$1 -> 0 | L10: ='[2]Base Inversionistas 26'!Q13/$N$1 -> 0
A11: BENITO HERRRA | D11: PTO. COLOM | E11: ='[2]Base Inversionistas 26'!J14/$N$1 -> 0 | F11: ='[2]Base Inversionistas 26'!K14/$N$1 -> 0 | G11: ='[2]Base Inversionistas 26'!L14/$N$1 -> 0 | H11: ='[2]Base Inversionistas 26'!M14/$N$1 -> 4 | I11: ='[2]Base Inversionistas 26'!N14/$N$1 -> 0 | J11: ='[2]Base Inversionistas 26'!O14/$N$1 -> 3 | K11: ='[2]Base Inversionistas 26'!P14/$N$1 -> 4 | L11: ='[2]Base Inversionistas 26'!Q14/$N$1 -> 0
A12: BIBIANA MONTOYA RODAS | E12: ='[2]Base Inversionistas 26'!J15/$N$1 -> 0 | F12: ='[2]Base Inversionistas 26'!K15/$N$1 -> 0 | G12: ='[2]Base Inversionistas 26'!L15/$N$1 -> 0 | H12: ='[2]Base Inversionistas 26'!M15/$N$1 -> 0 | I12: ='[2]Base Inversionistas 26'!N15/$N$1 -> 0 | J12: ='[2]Base Inversionistas 26'!O15/$N$1 -> 0 | K12: ='[2]Base Inversionistas 26'!P15/$N$1 -> 0 | L12: ='[2]Base Inversionistas 26'!Q15/$N$1 -> 0
A13: BRAYER ALEXIS QUINTERO FERNANDEZ | B13: 1090395092 | D13: CUCUTA | E13: ='[2]Base Inversionistas 26'!J16/$N$1 -> 1 | F13: ='[2]Base Inversionistas 26'!K16/$N$1 -> 1 | G13: ='[2]Base Inversionistas 26'!L16/$N$1 -> 0 | H13: ='[2]Base Inversionistas 26'!M16/$N$1 -> 3 | I13: ='[2]Base Inversionistas 26'!N16/$N$1 -> 0 | J13: ='[2]Base Inversionistas 26'!O16/$N$1 -> 1 | K13: ='[2]Base Inversionistas 26'!P16/$N$1 -> 1 | L13: ='[2]Base Inversionistas 26'!Q16/$N$1 -> 0
A14: CARLIS MICHELE PEREZ CANO | B14: 1095846194 | C14: 3022962452 | D14: BOGOTA | E14: ='[2]Base Inversionistas 26'!J17/$N$1 -> 1 | F14: ='[2]Base Inversionistas 26'!K17/$N$1 -> 1 | G14: ='[2]Base Inversionistas 26'!L17/$N$1 -> 0 | H14: ='[2]Base Inversionistas 26'!M17/$N$1 -> 0 | I14: ='[2]Base Inversionistas 26'!N17/$N$1 -> 0 | J14: ='[2]Base Inversionistas 26'!O17/$N$1 -> 0 | K14: ='[2]Base Inversionistas 26'!P17/$N$1 -> 0 | L14: ='[2]Base Inversionistas 26'!Q17/$N$1 -> 0
A15: CARLOS CARRASCO | D15: BOGOTA | E15: ='[2]Base Inversionistas 26'!J18/$N$1 -> 1 | F15: ='[2]Base Inversionistas 26'!K18/$N$1 -> 1 | G15: ='[2]Base Inversionistas 26'!L18/$N$1 -> 1 | H15: ='[2]Base Inversionistas 26'!M18/$N$1 -> 1 | I15: ='[2]Base Inversionistas 26'!N18/$N$1 -> 1 | J15: ='[2]Base Inversionistas 26'!O18/$N$1 -> 1.5 | K15: ='[2]Base Inversionistas 26'!P18/$N$1 -> 0 | L15: ='[2]Base Inversionistas 26'!Q18/$N$1 -> 0
A16: CARLOS PALMA | D16: BOGOTA | E16: ='[2]Base Inversionistas 26'!J19/$N$1 -> 0 | F16: ='[2]Base Inversionistas 26'!K19/$N$1 -> 2 | G16: ='[2]Base Inversionistas 26'!L19/$N$1 -> 1 | H16: ='[2]Base Inversionistas 26'!M19/$N$1 -> 1 | I16: ='[2]Base Inversionistas 26'!N19/$N$1 -> 1 | J16: ='[2]Base Inversionistas 26'!O19/$N$1 -> 0 | K16: ='[2]Base Inversionistas 26'!P19/$N$1 -> 0 | L16: ='[2]Base Inversionistas 26'!Q19/$N$1 -> 0
A17: CARLOS ANDRES COCUY | B17: 14797460 | C17: 3160438302 | D17: DOSQUEBRADAS | E17: ='[2]Base Inversionistas 26'!J20/$N$1 -> 1.125 | F17: ='[2]Base Inversionistas 26'!K20/$N$1 -> 1.125 | G17: ='[2]Base Inversionistas 26'!L20/$N$1 -> 1.25 | H17: ='[2]Base Inversionistas 26'!M20/$N$1 -> 1.5 | I17: ='[2]Base Inversionistas 26'!N20/$N$1 -> 0 | J17: ='[2]Base Inversionistas 26'!O20/$N$1 -> 0 | K17: ='[2]Base Inversionistas 26'!P20/$N$1 -> 1.5 | L17: ='[2]Base Inversionistas 26'!Q20/$N$1 -> 1
A18: CAROLINA QUIROGA | E18: ='[2]Base Inversionistas 26'!J21/$N$1 -> 0 | F18: ='[2]Base Inversionistas 26'!K21/$N$1 -> 0 | G18: ='[2]Base Inversionistas 26'!L21/$N$1 -> 0 | H18: ='[2]Base Inversionistas 26'!M21/$N$1 -> 1 | I18: ='[2]Base Inversionistas 26'!N21/$N$1 -> 1 | J18: ='[2]Base Inversionistas 26'!O21/$N$1 -> 0 | K18: ='[2]Base Inversionistas 26'!P21/$N$1 -> 0 | L18: ='[2]Base Inversionistas 26'!Q21/$N$1 -> 0
A19: CESAR VERA | B19: 79333423 | C19: 3166268412 | D19: BOGOTA | E19: ='[2]Base Inversionistas 26'!J22/$N$1 -> 5 | F19: ='[2]Base Inversionistas 26'!K22/$N$1 -> 4 | G19: ='[2]Base Inversionistas 26'!L22/$N$1 -> 4 | H19: ='[2]Base Inversionistas 26'!M22/$N$1 -> 5 | I19: ='[2]Base Inversionistas 26'!N22/$N$1 -> 2 | J19: ='[2]Base Inversionistas 26'!O22/$N$1 -> 10 | K19: ='[2]Base Inversionistas 26'!P22/$N$1 -> 7.75 | L19: ='[2]Base Inversionistas 26'!Q22/$N$1 -> 4
A20: CLAUDIA ARCINIEGAS | D20: CUCUTA | E20: ='[2]Base Inversionistas 26'!J23/$N$1 -> 0 | F20: ='[2]Base Inversionistas 26'!K23/$N$1 -> 0 | G20: ='[2]Base Inversionistas 26'!L23/$N$1 -> 0 | H20: ='[2]Base Inversionistas 26'!M23/$N$1 -> 0 | I20: ='[2]Base Inversionistas 26'!N23/$N$1 -> 1 | J20: ='[2]Base Inversionistas 26'!O23/$N$1 -> 0 | K20: ='[2]Base Inversionistas 26'!P23/$N$1 -> 0 | L20: ='[2]Base Inversionistas 26'!Q23/$N$1 -> 0
A21: DANIEL VARGAS | D21: NEIVA | E21: ='[2]Base Inversionistas 26'!J24/$N$1 -> 1 | F21: ='[2]Base Inversionistas 26'!K24/$N$1 -> 1.5 | G21: ='[2]Base Inversionistas 26'!L24/$N$1 -> 1.5 | H21: ='[2]Base Inversionistas 26'!M24/$N$1 -> 0 | I21: ='[2]Base Inversionistas 26'!N24/$N$1 -> 2 | J21: ='[2]Base Inversionistas 26'!O24/$N$1 -> 1 | K21: ='[2]Base Inversionistas 26'!P24/$N$1 -> 0 | L21: ='[2]Base Inversionistas 26'!Q24/$N$1 -> 0
A22: DANIELA CASTO | E22: ='[2]Base Inversionistas 26'!J25/$N$1 -> 0 | F22: ='[2]Base Inversionistas 26'!K25/$N$1 -> 0 | G22: ='[2]Base Inversionistas 26'!L25/$N$1 -> 0 | H22: ='[2]Base Inversionistas 26'!M25/$N$1 -> 0 | I22: ='[2]Base Inversionistas 26'!N25/$N$1 -> 0 | J22: ='[2]Base Inversionistas 26'!O25/$N$1 -> 0 | K22: ='[2]Base Inversionistas 26'!P25/$N$1 -> 0 | L22: ='[2]Base Inversionistas 26'!Q25/$N$1 -> 0
A23: DAVID MAESTRE | E23: ='[2]Base Inversionistas 26'!J26/$N$1 -> 0 | F23: ='[2]Base Inversionistas 26'!K26/$N$1 -> 0 | G23: ='[2]Base Inversionistas 26'!L26/$N$1 -> 0 | H23: ='[2]Base Inversionistas 26'!M26/$N$1 -> 0 | I23: ='[2]Base Inversionistas 26'!N26/$N$1 -> 0 | J23: ='[2]Base Inversionistas 26'!O26/$N$1 -> 0 | K23: ='[2]Base Inversionistas 26'!P26/$N$1 -> 0 | L23: ='[2]Base Inversionistas 26'!Q26/$N$1 -> 0
A24: DAVID MIRANDA | D24: BOGOTA | E24: ='[2]Base Inversionistas 26'!J27/$N$1 -> 1 | F24: ='[2]Base Inversionistas 26'!K27/$N$1 -> 0 | G24: ='[2]Base Inversionistas 26'!L27/$N$1 -> 0 | H24: ='[2]Base Inversionistas 26'!M27/$N$1 -> 2 | I24: ='[2]Base Inversionistas 26'!N27/$N$1 -> 1 | J24: ='[2]Base Inversionistas 26'!O27/$N$1 -> 0 | K24: ='[2]Base Inversionistas 26'!P27/$N$1 -> 3 | L24: ='[2]Base Inversionistas 26'!Q27/$N$1 -> 0
A25: EDDWARD GARCIA | D25: BOGOTA | E25: ='[2]Base Inversionistas 26'!J28/$N$1 -> 0 | F25: ='[2]Base Inversionistas 26'!K28/$N$1 -> 0 | G25: ='[2]Base Inversionistas 26'!L28/$N$1 -> 0 | H25: ='[2]Base Inversionistas 26'!M28/$N$1 -> 0 | I25: ='[2]Base Inversionistas 26'!N28/$N$1 -> 0 | J25: ='[2]Base Inversionistas 26'!O28/$N$1 -> 0 | K25: ='[2]Base Inversionistas 26'!P28/$N$1 -> 0 | L25: ='[2]Base Inversionistas 26'!Q28/$N$1 -> 0
A26: ERICA PLATA | B26: 60362206 | C26: 3165652640 | D26: LOS PATIOS | E26: ='[2]Base Inversionistas 26'!J29/$N$1 -> 0 | F26: ='[2]Base Inversionistas 26'!K29/$N$1 -> 1 | G26: ='[2]Base Inversionistas 26'!L29/$N$1 -> 1 | H26: ='[2]Base Inversionistas 26'!M29/$N$1 -> 1 | I26: ='[2]Base Inversionistas 26'!N29/$N$1 -> 1 | J26: ='[2]Base Inversionistas 26'!O29/$N$1 -> 0 | K26: ='[2]Base Inversionistas 26'!P29/$N$1 -> 0 | L26: ='[2]Base Inversionistas 26'!Q29/$N$1 -> 0
A27: ERMILGEN RIAÑO | D27: BOGOTA | E27: ='[2]Base Inversionistas 26'!J30/$N$1 -> 0 | F27: ='[2]Base Inversionistas 26'!K30/$N$1 -> 0 | G27: ='[2]Base Inversionistas 26'!L30/$N$1 -> 0 | H27: ='[2]Base Inversionistas 26'!M30/$N$1 -> 0 | I27: ='[2]Base Inversionistas 26'!N30/$N$1 -> 0 | J27: ='[2]Base Inversionistas 26'!O30/$N$1 -> 0 | K27: ='[2]Base Inversionistas 26'!P30/$N$1 -> 0 | L27: ='[2]Base Inversionistas 26'!Q30/$N$1 -> 0
